<?xml version="1.0" ?>
<robot name="manipulator">
    <material name="yellow">
        <color rgba="0.0 0.8 0.0 1.0" />
    </material>
    <material name="red">
        <color rgba="0.0 0.8 0.0 1.0" />
    </material>
    <material name="black">
        <color rgba="0.0 0.0 0.0 1.0" />
    </material>
    <material name="blue">
        <color rgba="0.0 0.0 0.0 1.0" />
    </material>
    <material name="white">
        <color rgba="0.0 0.0 0.0 1.0" />
    </material>
    <link name="world" />
    <!-- BASE LINK -->
    <link name="base_link">
        <visual>
            <origin rpy="0 0 0" xyz="0 0 0.01" />
            <material name="silver">
                <color rgba="0.75 0.75 0.75 1" />
            </material>
        </visual>
        <collision>
            <origin rpy="0 0 0" xyz="0 0 0.01" />
            <geometry>
                <cylinder length="0.02" radius="0.5" />
            </geometry>
        </collision>

<inertial>
            <mass value="0.1" />
            <inertia ixx="0.03" iyy="0.03" izz="0.03" ixy="0.0" ixz="0.0" iyz="0.0" />
        </inertial>

    </link>
    <gazebo reference="base_link">
        <material>Gazebo/White</material>
        <turnGravityOff>false</turnGravityOff>
    </gazebo>
    <!-- joint -->
    <joint name="fixed" type="fixed">
        <parent link="world" />
        <child link="base_link" />
    </joint>
    <!-- LINK 1 -->
    <link name="link1">
        <visual>
            <!-- <origin rpy="0 0 0" xyz="0 0 0.05" /> -->
            <origin rpy="0 0 0" xyz="0 0 0.065" />
            <!-- linknte paathi distance -->
            <geometry>
                <cylinder length="0.13" radius="0.40" />
            </geometry>
            <material name="silver">
                <color rgba="0.75 0.75 0.75 1" />
            </material>
        </visual>
        <collision>
            <origin rpy="0 0 0" xyz="0 0 0.065" />
            <geometry>
                <cylinder length="0.130" radius="0.40" />
            </geometry>
        </collision>

<inertial>
            <mass value="0.1" />
            <inertia ixx="0.03" iyy="0.03" izz="0.03" ixy="0.0" ixz="0.0" iyz="0.0" />
        </inertial>

    </link>
    <gazebo reference="link1">
        <material>Gazebo/Black</material>
        <turnGravityOff>false</turnGravityOff>
    </gazebo>
    <!-- JOINT 1 -->
    <joint name="joint1" type="revolute">
        <!-- <origin rpy="0 0 0" xyz="0 0 0.01" /> -->
        <origin rpy="0 0 0" xyz="0 0 0" />
        <!--parent linknte distance -->
        <parent link="base_link" />
        <child link="link1" />
        <axis xyz="0 0 1" />
        <limit lower="-6.28" upper="6.28" effort="100" velocity="1" />
        <dynamics damping="0.01" friction="0.01" />
    </joint>
    <!-- LINK 2 -->
    <link name="link2">
        <visual>
            <!-- <origin rpy="0 0 0" xyz="0 0 0.15" /> -->
            <origin rpy="0 0 0" xyz="0 0 0.17" />
            <geometry>
                <cylinder length="0.34" radius="0.09" />
            </geometry>
            <material name="silver">
                <color rgba="0.75 0.75 0.75 1" />
            </material>
        </visual>
        <collision>
            <!-- <origin rpy="0 0 0" xyz="0 0 0.15" /> -->
            <origin rpy="0 0 0" xyz="0 0 0.125" />
            <geometry>
                <cylinder length="0.25" radius="0.09" />
            </geometry>
        </collision>

<inertial>
            <mass value="0.1" />
            <inertia ixx="0.03" iyy="0.03" izz="0.03" ixy="0.0" ixz="0.0" iyz="0.0" />
        </inertial>

    </link>
    <gazebo reference="link2">
        <material>Gazebo/Blue</material>
        <turnGravityOff>false</turnGravityOff>
    </gazebo>
    <!-- JOINT 2 -->
    <joint name="joint2" type="revolute">
        <origin rpy="0 0 0" xyz="0 0 0.26" />
        <parent link="link1" />
        <child link="link2" />
        <axis xyz="0 1 0" />
        <limit lower="-1.4835" upper="1.4835" effort="100" velocity="1" />
        <dynamics damping="0.01" friction="0.01" />
    </joint>
    <!-- LINK 3 -->
    <link name="link3">
        <visual>
            <!-- <origin rpy="0 0 0" xyz="0 0 0.15" /> -->
            <origin rpy="0 0 0" xyz="0 0 0.17" />
            <geometry>
                <cylinder length="0.340" radius="0.055" />
            </geometry>
            <material name="silver">
                <color rgba="0.75 0.75 0.75 1" />
            </material>
        </visual>
        <collision>
            <!-- <origin rpy="0 0 0" xyz="0 0 0.15" /> -->
            <origin rpy="0 0 0" xyz="0 0 0.125" />
            <geometry>
                <cylinder length="0.25" radius="0.055" />
            </geometry>
        </collision>

<inertial>
            <mass value="0.1" />
            <inertia ixx="0.03" iyy="0.03" izz="0.03" ixy="0.0" ixz="0.0" iyz="0.0" />
        </inertial>

    </link>
    <gazebo reference="link3">
        <material>Gazebo/Black</material>
        <turnGravityOff>false</turnGravityOff>
    </gazebo>
    <!-- JOINT 3 -->
    <joint name="joint3" type="revolute">
        <origin rpy="0 0 0" xyz="0 0 0.32" />
        <parent link="link2" />
        <child link="link3" />
        <axis xyz="0 1 0" />
        <limit lower="-1.4835" upper="0.15" effort="100" velocity="1" />
        <dynamics damping="0.01" friction="0.01" />
    </joint>
    <!-- LINK 4 -->
    <link name="link4">
        <visual>
            <!-- <origin rpy="0 0 0" xyz="0 0 0.05" /> -->
            <origin rpy="0 0 0" xyz="0 0 0.09" />
            <geometry>
                <!-- <box size="0.03 0.03 0.1" /> -->
                <cylinder length="0.180" radius="0.04" />
            </geometry>
            <material name="silver">
                <color rgba="0.75 0.75 0.75 1" />
            </material>
        </visual>
        <collision>
            <!-- <origin rpy="0 0 0" xyz="0 0 0.05" /> -->
            <origin rpy="0 0 0" xyz="0 0 0.45" />
            <geometry>
                <!-- <box size="0.03 0.03 0.1" /> -->
                <cylinder length="0.09" radius="0.04" />
            </geometry>
        </collision>

<inertial>
            <mass value="0.1" />
            <inertia ixx="0.03" iyy="0.03" izz="0.03" ixy="0.0" ixz="0.0" iyz="0.0" />
        </inertial>

    </link>
    <gazebo reference="link4">
        <material>Gazebo/Blue</material>
        <turnGravityOff>false</turnGravityOff>
    </gazebo>
    <!-- JOINT 4 -->
    <joint name="joint4" type="revolute">
        <origin rpy="0 0 0" xyz="0 0 0.32" />
        <parent link="link3" />
        <child link="link4" />
        <axis xyz="0 1 0" />
        <limit lower="-1.4835" upper="1.4835" effort="100" velocity="1" />
        <dynamics damping="0.01" friction="0.01" />
    </joint>
    <!-- LINK 5 -->
    <link name="link5">
        <visual>
            <!-- <origin rpy="0 0 0" xyz="0 0 0.05" /> is always in the middle of the geomtry-->
            <origin rpy="0 0 0" xyz="0 0 0.11" />
            <geometry>
                <box size="0.06 0.06 0.22" />
            </geometry>
            <material name="silver">
                <color rgba="0.75 0.75 0.75 1" />
            </material>
        </visual>
        <collision>
            <!-- <origin rpy="0 0 0" xyz="0 0 0.05" /> -->
            <origin rpy="0 0 0" xyz="0 0 0.05" />
            <geometry>
                <box size="0.06 0.06 0.1" />
            </geometry>
        </collision>

<inertial>
            <mass value="0.1" />
            <inertia ixx="0.03" iyy="0.03" izz="0.03" ixy="0.0" ixz="0.0" iyz="0.0" />
        </inertial>

    </link>
    <gazebo reference="link5">
        <material>Gazebo/Black</material>
        <turnGravityOff>false</turnGravityOff>
    </gazebo>
    <!-- JOINT 5 -->
    <joint name="joint5" type="revolute">
        <origin rpy="0 0 0" xyz="0 0 0.16" />
        <parent link="link4" />
        <child link="link5" />
        <axis xyz="0 0 1" />
        <limit lower="-1.72" upper="1.72" effort="100" velocity="1" />
        <dynamics damping="0.01" friction="0.01" />
    </joint>
    <!-- LINK 6 -->
    <link name="link6">
        <visual>
            <!-- <origin rpy="0 0 0" xyz="0 0 0.05" /> -->
            <origin rpy="0 0 0" xyz="0 0 0.075" />
            <geometry>
                <cylinder length="0.15" radius="0.04" />
            </geometry>
            <material name="silver">
                <color rgba="0.75 0.75 0.75 1" />
            </material>
            <material name="Blue" />
        </visual>
        <collision>
            <!-- <origin rpy="0 0 0" xyz="0 0 0.05" /> -->
            <origin rpy="0 0 0" xyz="0 0 0.05" />
            <geometry>
                <cylinder length="0.10" radius="0.03" />
            </geometry>
        </collision>

<inertial>
            <mass value="0.1" />
            <inertia ixx="0.03" iyy="0.03" izz="0.03" ixy="0.0" ixz="0.0" iyz="0.0" />
        </inertial>

    </link>
    <gazebo reference="link6">
        <material>Gazebo/Blue</material>
        <turnGravityOff>false</turnGravityOff>
    </gazebo>
    <!-- JOINT 6 -->
    <joint name="joint6" type="revolute">
        <origin rpy="0 0 0" xyz="0 0 0.23" />
        <parent link="link5" />
        <child link="link6" />
        <axis xyz="0 1 0" />
        <limit lower="-1.4835" upper="1.4835" effort="100" velocity="1" />
        <dynamics damping="0.01" friction="0.01" />
    </joint>


    <link name="link7">
        <visual>
            <origin rpy="0 0 0" xyz="0 0 -0.075" />
            <geometry>
                <box size="0.02 0.02 0.15" />
            </geometry>
            <material name="silver">
                <color rgba="0.75 0.75 0.75 1" />
            </material>
        </visual>
        <collision>
            <origin rpy="0 0 0" xyz="0 0 -0.075" />
            <geometry>
                <box size="0.02 0.02 0.15" />
            </geometry>
            <material name="blue">
                <color rgba="0 0 0.75 1" />
            </material>

        </collision>

        <inertial>
            <mass value="0.1" />
            <inertia ixx="0.03" iyy="0.03" izz="0.03" ixy="0.0" ixz="0.0" iyz="0.0" />
        </inertial>
    </link>

    <gazebo reference="link7">
        <material>Gazebo/Blue</material>
        <turnGravityOff>false</turnGravityOff>
    </gazebo>

    <joint name="joint7" type="revolute">
        <origin rpy="0 0 0" xyz="0 0 0.264" />
        <parent link="link6" />
        <child link="link7" />
        <axis xyz="0 0 1" />
        <limit lower="-3.14" upper="3.14" effort="100" velocity="1" />
        <dynamics damping="0.01" friction="0.01" />
    </joint>


    <link name="tcp">
        <visual>
            <origin rpy="0 0 0" xyz="0 0 0" />
            <geometry>
                <box size="0 0 0" />
            </geometry>
            <material name="silver">
                <color rgba="0.75 0.75 0.75 1" />
            </material>
        </visual>
        <collision>
            <origin rpy="0 0 0" xyz="0 0 0" />
            <geometry>
                <box size="0 0 0" />
            </geometry>
            <material name="blue">
                <color rgba="0 0 0.75 1" />
            </material>

        </collision>

        <inertial>
            <mass value="0.1" />
            <inertia ixx="0.03" iyy="0.03" izz="0.03" ixy="0.0" ixz="0.0" iyz="0.0" />
        </inertial>
    </link>

    <gazebo reference="tcp">
        <material>Gazebo/Blue</material>
        <turnGravityOff>false</turnGravityOff>
    </gazebo>

    <joint name="joint7_tcp" type="fixed">
        <origin rpy="0 0 0" xyz="0 0 0" />
        <parent link="link7" />
        <child link="tcp" />
    </joint>

    <!-- <link name="TCP">
        <visual>
            <origin rpy="0 0 0" xyz="0 0 0" />
        </visual>
        <collision>
            <origin rpy="0 0 0" xyz="0 0 0" />
        </collision>

<inertial>
            <mass value="0.1" />
            <inertia ixx="0.03" iyy="0.03" izz="0.03" ixy="0.0" ixz="0.0" iyz="0.0" />
        </inertial>

    </link>
    <joint name="joint6_TCP" type="fixed">
        <parent link="joint6" />
        <child link="TCP" />
        <origin xyz="0 0 0.2" />
    </joint> -->


<transmission name="trans_joint1">
        <type>transmission_interface/SimpleTransmission</type>
        <joint name="joint1">
            <hardwareInterface>hardware_interface/PositionJointInterface</hardwareInterface>
        </joint>
        <actuator name="joint1_motor">
            <hardwareInterface>hardware_interface/PositionJointInterface</hardwareInterface>
            <mechanicalReduction>1</mechanicalReduction>
        </actuator>
    </transmission>
    <transmission name="trans_joint2">
        <type>transmission_interface/SimpleTransmission</type>
        <joint name="joint2">
            <hardwareInterface>hardware_interface/PositionJointInterface</hardwareInterface>
        </joint>
        <actuator name="joint2_motor">
            <hardwareInterface>hardware_interface/PositionJointInterface</hardwareInterface>
            <mechanicalReduction>1</mechanicalReduction>
        </actuator>
    </transmission>
    <transmission name="trans_joint3">
        <type>transmission_interface/SimpleTransmission</type>
        <joint name="joint3">
            <hardwareInterface>hardware_interface/PositionJointInterface</hardwareInterface>
        </joint>
        <actuator name="joint3_motor">
            <hardwareInterface>hardware_interface/PositionJointInterface</hardwareInterface>
            <mechanicalReduction>1</mechanicalReduction>
        </actuator>
    </transmission>
    <transmission name="trans_joint4">
        <type>transmission_interface/SimpleTransmission</type>
        <joint name="joint4">
            <hardwareInterface>hardware_interface/PositionJointInterface</hardwareInterface>
        </joint>
        <actuator name="joint4_motor">
            <hardwareInterface>hardware_interface/PositionJointInterface</hardwareInterface>
            <mechanicalReduction>1</mechanicalReduction>
        </actuator>
    </transmission>
    <transmission name="trans_joint5">
        <type>transmission_interface/SimpleTransmission</type>
        <joint name="joint5">
            <hardwareInterface>hardware_interface/PositionJointInterface</hardwareInterface>
        </joint>
        <actuator name="joint5_motor">
            <hardwareInterface>hardware_interface/PositionJointInterface</hardwareInterface>
            <mechanicalReduction>1</mechanicalReduction>
        </actuator>
    </transmission>
    <transmission name="trans_joint6">
        <type>transmission_interface/SimpleTransmission</type>
        <joint name="joint6">
            <hardwareInterface>hardware_interface/PositionJointInterface</hardwareInterface>
        </joint>
        <actuator name="joint6_motor">
            <hardwareInterface>hardware_interface/PositionJointInterface</hardwareInterface>
            <mechanicalReduction>1</mechanicalReduction>
        </actuator>
    </transmission>
    <transmission name="trans_joint7">
        <type>transmission_interface/SimpleTransmission</type>
        <joint name="joint7">
            <hardwareInterface>hardware_interface/PositionJointInterface</hardwareInterface>
        </joint>
        <actuator name="joint7_motor">
            <hardwareInterface>hardware_interface/PositionJointInterface</hardwareInterface>
            <mechanicalReduction>1</mechanicalReduction>
        </actuator>
    </transmission>
    <gazebo>
        <plugin name="gazebo_ros_control" filename="libgazebo_ros_control.so">
            <robotNamespace>/</robotNamespace>
        </plugin>
    </gazebo>
    <gazebo>
        <plugin name="gazebo_grasp_fix" filename="libgazebo_grasp_fix.so">
            <arm>
                <arm_name>arm</arm_name>
                <palm_link>link6</palm_link>
            </arm>
            <forces_angle_tolerance>100</forces_angle_tolerance>
            <update_rate>4</update_rate>
            <grip_count_threshold>4</grip_count_threshold>
            <max_grip_count>8</max_grip_count>
            <release_tolerance>0.005</release_tolerance>
            <disable_collisions_on_attach>false</disable_collisions_on_attach>
            <contact_topic>__default_topic__</contact_topic>
        </plugin>
    </gazebo>
</robot>
